Traceback (most recent call last):
  File "/opt/hostedtoolcache/Python/3.9.16/x64/lib/python3.9/site-packages/jupyter_cache/executors/utils.py", line 58, in single_nb_execution
    executenb(
  File "/opt/hostedtoolcache/Python/3.9.16/x64/lib/python3.9/site-packages/nbclient/client.py", line 1305, in execute
    return NotebookClient(nb=nb, resources=resources, km=km, **kwargs).execute()
  File "/opt/hostedtoolcache/Python/3.9.16/x64/lib/python3.9/site-packages/jupyter_core/utils/__init__.py", line 166, in wrapped
    return loop.run_until_complete(inner)
  File "/opt/hostedtoolcache/Python/3.9.16/x64/lib/python3.9/asyncio/base_events.py", line 647, in run_until_complete
    return future.result()
  File "/opt/hostedtoolcache/Python/3.9.16/x64/lib/python3.9/site-packages/nbclient/client.py", line 705, in async_execute
    await self.async_execute_cell(
  File "/opt/hostedtoolcache/Python/3.9.16/x64/lib/python3.9/site-packages/nbclient/client.py", line 1058, in async_execute_cell
    await self._check_raise_for_error(cell, cell_index, exec_reply)
  File "/opt/hostedtoolcache/Python/3.9.16/x64/lib/python3.9/site-packages/nbclient/client.py", line 914, in _check_raise_for_error
    raise CellExecutionError.from_cell_and_msg(cell, exec_reply_content)
nbclient.exceptions.CellExecutionError: An error occurred while executing the following cell:
------------------
import scipy.stats

races = ["Black, non-Hispanic", "White, non-Hispanic", "Hispanic", "Other, non-Hispanic"]
for i in range(len(races)):
    for j in range(i, len(races)):
        race1, race2 = races[i], races[j]
        if race1 != race2:
            print(race1, race2, scipy.stats.ttest_ind(multitest_ca[multitest_ca["Stratification1"] == race1]["DataValue"],
                      multitest_ca[multitest_ca["Stratification1"] == race2]["DataValue"], axis=0, equal_var=False))
------------------


[0;31m---------------------------------------------------------------------------[0m
[0;31mNameError[0m                                 Traceback (most recent call last)
Cell [0;32mIn[10], line 8[0m
[1;32m      6[0m race1, race2 [38;5;241m=[39m races[i], races[j]
[1;32m      7[0m [38;5;28;01mif[39;00m race1 [38;5;241m!=[39m race2:
[0;32m----> 8[0m     [38;5;28mprint[39m(race1, race2, scipy[38;5;241m.[39mstats[38;5;241m.[39mttest_ind([43mmultitest_ca[49m[multitest_ca[[38;5;124m"[39m[38;5;124mStratification1[39m[38;5;124m"[39m] [38;5;241m==[39m race1][[38;5;124m"[39m[38;5;124mDataValue[39m[38;5;124m"[39m],
[1;32m      9[0m               multitest_ca[multitest_ca[[38;5;124m"[39m[38;5;124mStratification1[39m[38;5;124m"[39m] [38;5;241m==[39m race2][[38;5;124m"[39m[38;5;124mDataValue[39m[38;5;124m"[39m], axis[38;5;241m=[39m[38;5;241m0[39m, equal_var[38;5;241m=[39m[38;5;28;01mFalse[39;00m))

[0;31mNameError[0m: name 'multitest_ca' is not defined

